Workbook

Sheet Macro Assumptions
A1: NSWDF 10-Year Capital Market Assumptions — Macro Anchors
A2: Forecast horizon: 10 years from 2 April 2026 | Author: WaterNSW Treasury Team | Updated: May 2026 — incorporating AI boom, supply-chain reshoring & geopolitical risk overlay
A4: Variable | B4: 10Y Avg / Endpoint | C4: Format | D4: Rationale (PM Judgement) | E4: Anchor / Source | F4: Change vs Prior CMA
A5: COLOUR CODE: Blue = hardcoded input Green = formula linked to other cell in this sheet Black = derived formula Cells shaded YELLOW = key assumption requiring attention
A6: 1. Inflation (10-year average)
A7: Australian CPI (headline, YoY) | B7: 0.026 | C7: % | D7: RBA 2–3% target band: we sit 10 bps above the prior 2.50% midpoint assumption at 2.60%. Three structural forces lift the 10Y average: (i) AI data-centre energy demand adds an estimated +10–15 bps to electricity CPI annually as data-centre build-out pushes baseload demand; (ii) supply-chain reshoring raises goods-import costs — domestically produced substitutes carry 15–25% cost premiums over legacy Asian manufacturing; and (iii) geopolitical risk premia (sanctions, shipping disruptions, critical-minerals export controls) embed a persistent +5–10 bps tradeable-goods premium. Partially offset by AI-driven productivity in services (wage-bill compression in administrative roles, ~−10 bps). Labour market remains structurally tight; rents and insurance lead services persistence. Net: 2.60%, skewed to the upside. | E7: RBA SoMP (May 2026); ABS CPI 6401.0; RBA energy-transition research; OECD reshoring cost study | F7: +10 bps vs prior (2.50% → 2.60%)
A8: US CPI (headline, YoY) | B8: 0.027 | C8: % | D8: Revised materially higher to 2.70% (was 2.40%). The Trump tariff regime (April 2026 "Liberation Day" tariffs averaging 25–30% on a broad import basket) represents the most significant supply-side inflation shock since COVID. Fed research and our internal model estimate a +0.4–0.6% CPI first-round pass-through, with ~40% persistence over 3–5 years as producers rebase supply chains. Reshoring adds a structural goods-cost premium: domestic manufacturing carries 20–35% unit-cost disadvantage vs offshore. Services inflation (shelter, medical, insurance) remains structurally anchored at 3.5–4.0% — a structural ceiling, not a peak. AI partially offsets via disinflationary productivity in software, logistics and back-office services (~−15 bps). Fed CPI typically prints 30–40 bps above PCE; PCE target of 2% implies CPI structural floor ~2.3–2.4%. Our 2.70% reflects tariff persistence + services stickiness, landing well above the old 2.40% assumption. | E8: Fed SEP (Mar 2026); BLS CPI; FOMC dot plot; Fed staff tariff pass-through analysis; BIS reshoring papers | F8: +30 bps vs prior (2.40% → 2.70%)
A9: ↳ AU CPI decomposition: Energy +0.15% | Shelter/Rents +0.90% | Tradeable goods +0.40% | AI-offset −0.10% | Other services +1.25% = 2.60%
A10: 2. Real GDP growth (10-year average)
A11: Australian real GDP growth | B11: 0.021 | C11: % | D11: Revised to 2.10% (was 2.00%). Supply-side: population growth ~1.35% + structural productivity ~0.75% (lifted 10 bps from prior by AI adoption in mining, financial services and professional services). Australia benefits from a critical-minerals supercycle 2.0: lithium, cobalt, copper and rare earths are essential inputs for AI hardware and energy transition — adds ~+0.15% to resources sector GDP. Headwinds: (i) geopolitical de-globalisation reduces export market optionality; (ii) fiscal consolidation from elevated defence spend; (iii) housing supply constraint depresses dwelling investment. AI tailwind arrives 2–3 years later in Australia vs US (software/services sector smaller as share of GDP). Net: 2.10%, back-half weighted. | E11: Treasury IGR 2023; RBA SoMP; IMF WEO (Apr 2026); CSIRO AI economy modelling; Geoscience Australia critical minerals | F11: +10 bps vs prior (2.00% → 2.10%)
A12: US real GDP growth | B12: 0.021 | C12: % | D12: Revised to 2.10% (was 1.80%). The AI productivity boom is the dominant upward revision. Historical analogues (electricity adoption 1920s, IT revolution 1990s) suggest TFP uplift of +0.3–0.5% p.a. once diffusion exceeds ~30% of firms (expected by 2027–28). We adopt a conservative +0.30% premium to CBO's 1.80% potential, recognising implementation lags. Tariff headwinds partially offset: 25–30% broad tariffs reduce trade efficiency, contributing an estimated −0.15% to −0.25% GDP drag (IMF tariff multiplier estimates). Reshoring manufacturing is labour-intensive and investment-intensive — creates a short-run boost but steady-state productivity drag. Geopolitical risk: supply chain diversification raises capex but also spreads risk. Labour force growth: slowing (immigration reform), capping potential. Net: CBO 1.80% + AI +0.30% − tariff drag 0.10% ≈ 2.00–2.10%. | E12: CBO Long-Term Budget Outlook (2026); Fed SEP; McKinsey AI productivity modelling; IMF tariff multiplier research | F12: +30 bps vs prior (1.80% → 2.10%)
A13: Australian nominal GDP (derived) | B13: ='Macro Assumptions'!$B$7+'Macro Assumptions'!$B$11 -> 0.047 | C13: % | D13: Anchor for ASX EPS growth and listed property DPS growth. Links to AU CPI (B7) + AU real GDP (B11). | E13: Derived — formula links to rows 7 & 11 | F13: +20 bps implied (4.70% vs 4.50%)
A14: US nominal GDP (derived) | B14: ='Macro Assumptions'!$B$8+'Macro Assumptions'!$B$12 -> 0.048 | C14: % | D14: Anchor for global ex-Aus EPS growth. Links to US CPI (B8) + US real GDP (B12). | E14: Derived — formula links to rows 8 & 12 | F14: +60 bps implied (4.80% vs 4.20%)
A15: 3. Neutral / 10Y average policy rates
A16: RBA cash rate (10Y average) | B16: 0.0335 | C16: % | D16: Revised to 3.35% (was 3.25%). Neutral nominal rate = neutral real + long-run CPI. RBA's estimated neutral real rate: ~0.75% (per RBA Bulletin). With AU CPI revised to 2.60%, implied neutral nominal = 3.35%. The 10Y average will include an early-cycle easing phase (RBA likely to cut 50–75 bps by end-2026 as disinflation consolidates) followed by renormalisation. Structurally, higher government borrowing for defence and energy transition keeps the term premium elevated. AI capex boom raises the return on capital, supporting a slightly higher neutral rate than 2010s estimates. Full cycle average lands at ~3.35%. | E16: RBA Bulletin: neutral rate (2025); OIS forward curve; RBA SoMP May 2026 | F16: +10 bps vs prior (3.25% → 3.35%)
A17: Fed funds rate (10Y average) | B17: 0.032 | C17: % | D17: Revised to 3.20% (was 3.00%). Neutral real ~0.50% (HLW/FRB NY r-star) + US CPI 2.70% = 3.20%. Key drivers: (i) Tariff shock delays the rate-cutting cycle — Fed unlikely to deliver more than 50 bps of cuts through 2026 as CPI stays above 2.5%; (ii) AI investment boom is capital-intensive, raising the equilibrium real rate (as Summers/Rachel-Summers predict when fiscal policy and investment both expand); (iii) treasury supply surge (deficit financing) keeps term premium structurally positive. Slightly below RBA, supporting a 15 bps positive AUD-USD hedge carry (vs prior 25 bps). | E17: FOMC SEP (Mar 2026); HLW r-star (FRBNY); Fed staff r* estimates; CBO deficit projections | F17: +20 bps vs prior (3.00% → 3.20%)
A18: 4. AUD/USD currency assumptions
A19: AUD/USD spot (2 April 2026) | B19: 0.637 | C19: rate | D19: Updated to 0.6370 (was 0.6500). AUD weakened sharply on Liberation Day tariff shock (April 2026) as iron ore futures fell ~12% and risk-off USD demand surged. Chinese growth outlook deteriorated — a major AUD headwind given ~35% of exports. Current levels are below OECD PPP fair value (~0.68–0.72), implying the AUD is cheap. | E19: RBA daily rates; Refinitiv FX spot (project date); Bloomberg AUD pricing | F19: −1.3 cents vs prior (0.6500 → 0.6370)
A20: AUD/USD 10Y target (PPP-anchored) | B20: 0.7 | C20: rate | D20: Revised slightly to 0.70 (was 0.71). Bull case for AUD: (i) critical-minerals supercycle improves terms of trade — lithium, copper, cobalt export revenues rise as AI hardware and energy transition demand spikes; (ii) deep undervaluation relative to OECD PPP (0.68–0.72 range) provides reversion support; (iii) diversification away from USD in global reserves is a slow structural tailwind. Bear case: (i) USD stays structurally stronger as US AI investment requires capital inflows priced in USD; (ii) China slowdown structurally reduces commodity demand; (iii) geopolitical fragmentation compresses global trade growth — hurts small, open commodity exporters like Australia. Net: 0.70, skewed slightly to the downside vs prior. AU CPI exceeds US CPI by ~−10 bps p.a., so PPP drifts marginally down over the horizon. | E20: OECD PPP database; IMF REER; Refinitiv LR FX consensus; RBA ToT analysis; critical minerals export research | F20: −1 cent vs prior (0.7100 → 0.7000)
A21: Implied AUD appreciation vs USD (annualised) | B21: =('Macro Assumptions'!$B$20/'Macro Assumptions'!$B$19)^(1/10)-1 -> 0.0094756806 | C21: % | D21: Geometric annualised drift from spot to 10Y target. Drives FX contribution for unhedged global assets. | E21: Derived
A22: FX drag on USD assets for AUD investor (annualised) | B22: =-('Macro Assumptions'!$B$21) -> -0.0094756806 | C22: % | D22: Mirror of AUD appreciation — an AUD investor in USD assets loses ~this amount annually from currency. | E22: Derived
A23: FX drag on global ACWI ex-Aus basket (AUD investor) | B23: -0.0065 | C23: % | D23: MSCI ACWI ex-Aus: ~62% USD, ~12% EUR, ~6% JPY, ~3% GBP, balance DM/EM. AUD typically appreciates less vs EUR/JPY; blended drag slightly smaller. Revised to −0.65% (was −0.70%) as USD dominance in AI-related capex partially reduces EUR/JPY weights in effective basket. | E23: MSCI ACWI ex-Aus FX composition; Refinitiv
A24: AUD-USD hedge return contribution (AU cash − US cash) | B24: ='Macro Assumptions'!$B$16-'Macro Assumptions'!$B$17 -> 0.0015 | C24: % | D24: Positive carry for AUD investor hedging USD exposure. Narrowed to ~15 bps (was 25 bps) as Fed rate revised up by more than RBA. Monitor for inversion risk. | E24: Covered interest parity; revised rate differential
A25: 5. Thematic & Structural Risk Overlay (NEW — informational; feeds qualitative valuation drift adjustments in Asset Class tab)
A26: AI Productivity Premium (US economy, p.a.) | B26: 0.003 | C26: % | D26: Conservative adoption scenario. Historical IT productivity analogues (Brynjolfsson, Baily-Montalbano) suggest +0.3–0.5% TFP uplift once diffusion >30% of firms. AI adoption in US financial services, healthcare, logistics, and professional services already exceeding 30% by 2026. Manufacturing and education adoption trails. We adopt lower-bound +0.30%. Feeds into higher US real GDP (row 12) and supports US EPS growth premium for global equity forecasts. | E26: McKinsey Global Institute (2024); Brynjolfsson et al. AI productivity research; NBER Working Paper 31161; Goldman Sachs Global Investment Research AI impact study | F26: +0.30% p.a. — NEW assumption
A27: AI Productivity Premium (Australia, p.a.) | B27: 0.001 | C27: % | D27: Australia's AI adoption lags US by ~2–3 years (smaller software/tech sector as % GDP, regulatory caution, skills gap). Critical uplift: mining automation, financial services back-office, healthcare admin. Construction and resources dominate AU capex — lower AI intensity. Net productivity premium: +0.10% p.a., back-half weighted (materialises 2028–2033 in forecast window). | E27: CSIRO AI Roadmap; Productivity Commission Digital Economy paper; RBA research on productivity | F27: +0.10% p.a. — NEW assumption
A28: Supply Chain Reshoring — Goods Inflation Premium (US) | B28: 0.002 | C28: % | D28: Broad tariff regime (April 2026) has triggered accelerated reshoring across semiconductors, pharmaceuticals, EVs, and consumer electronics. Domestic manufacturing unit costs carry a 20–35% premium over prior Asian supply chains. Pass-through to CPI: ~+0.20% p.a. persistent (firms rebuild margin after cost shock). This is the primary driver of our US CPI revision. Partially absorbed by AI-driven manufacturing efficiency (robotics, process automation). | E28: Federal Reserve Bank of NY supply chain research; BIS Working Paper on reshoring costs; JPMorgan tariff pass-through modelling | F28: +0.20% p.a. goods inflation — feeds US CPI row 8
A29: Geopolitical Risk Premium on Commodity/Energy Prices | B29: 0.001 | C29: % | D29: Russia-Ukraine war, Middle East tensions, Taiwan Strait risk and increasing sanctions regimes add a structural risk premium to energy and commodity prices. Shipping disruption (Red Sea, Strait of Hormuz) raises freight costs ~15–20% above pre-2020 norms. We embed +10 bps as a persistent macro overlay on both AU and US inflation — not a spike scenario, but a floor. This risk is asymmetric to the upside (escalation scenario = +30–50 bps CPI). | E29: IEA energy security reports; RAND geopolitical risk studies; Baltic Exchange shipping indices | F29: +10 bps CPI overlay — embedded in rows 7 & 8
A30: Global Trade Volume Drag (tariff & de-globalisation) | B30: -0.002 | C30: % | D30: IMF estimates broad 25–30% US tariffs reduce global trade volumes by 3–5%. De-globalisation trend (friend-shoring, supply-chain regionalisation) reduces trade multiplier efficiency. Impact on global GDP: −0.2% drag on the 10Y average (front-loaded, diminishing as new supply chains establish). Mechanically reduces export revenue for AUD (iron ore, LNG, agriculture) and global EPS growth assumptions in the asset class tab. | E30: IMF World Economic Outlook (Apr 2026); WTO trade outlook; OECD trade policy simulations | F30: −0.20% global GDP drag — feeds global equity valuation drift
A31: Critical Minerals Cycle — AU Terms of Trade Boost | B31: 0.0015 | C31: % | D31: AI hardware build-out (NVIDIA GPUs, data centre power infrastructure) and energy transition (EVs, grid storage) creates a decade-long demand super-cycle for lithium, cobalt, copper, nickel, and rare earths — all significant Australian export categories. With supply constrained (long lead times, permitting, geopolitical concentration risks), we embed +15 bps AU ToT uplift p.a., partially offsetting iron ore softness from China slowdown. Supports AUD at higher levels vs USD through the window. | E31: Geoscience Australia critical minerals outlook; IEA critical minerals report (2025); S&P Global Market Intelligence commodity forecasts | F31: +15 bps AU GDP tailwind — NEW, partially offsets iron ore drag
A32: AI Energy Demand — Impact on AU Electricity CPI | B32: 0.0015 | C32: % | D32: Global data centre power consumption is projected to grow 10–15% p.a. through 2030. Australia is attracting significant hyperscaler investment (Microsoft, Google, AWS) given political stability, renewable energy potential, and proximity to APAC. Near-term: baseload power demand exceeds renewable supply growth, pushing electricity prices higher (+8–12% p.a. for commercial). CPI direct weight: electricity ~2.3% of basket; adds ~+15 bps to headline AU CPI. Medium-term (2029+): large-scale renewables + battery storage bring prices back. Net 10Y average: +15 bps. Embedded in AU CPI row 7. | E32: AEMO ISP (2024); IEA Data Centres & AI electricity demand (2026); ABS CPI basket weights | F32: +15 bps AU CPI — embedded in row 7
A34: NOTES: All values are 10-year geometric averages. BLUE = hardcoded input. GREEN = formula. YELLOW highlight = changed from prior CMA. Section 5 factors are informational — they feed qualitatively into asset-class rationale and quantitatively into revised CPI/GDP rows above. AI Acknowledgement: Claude (claude-sonnet-4-6) assisted in structuring this overlay; all judgements and numbers remain those of the WaterNSW Treasury Team.

Sheet Asset Class Forecasts
A1: NSWDF 10-Year Asset Class Forecasts — Building Block Decomposition
A2: All returns are gross of fees, in AUD, annualised over 10 years from 2 April 2026. Apply asset class costs (IM Table 3A) and trust-level fees (IM Table 4A) when rolling up to STI/MTG/LTG.
A4: Asset Class | B4: Proxy Index (IM) | C4: Starting Yield | D4: Real / Growth | E4: Term Premium | F4: Credit Spread | G4: Default Losses | H4: Valuation Drift | I4: Illiquidity / Leverage | J4: FX Contribution | K4: Hedge Return | L4: Forecast Return (10Y) | M4: Forecast Risk (vol) | N4: Notes / Rationale
A5: Cash | B5: Bloomberg AusBond Bank Bill Index | C5: ='Macro Assumptions'!$B$16 -> 0.0335 | L5: =IF(ISBLANK(C5),0,C5)+IF(ISBLANK(D5),0,D5)+IF(ISBLANK(E5),0,E5)+IF(ISBLANK(F5),0,F5)+IF(ISBLANK(G5),0,G5)+IF(ISBLANK(H5),0,H5)+IF(ISBLANK(I5),0,I5)+IF(ISBLANK(J5),0,J5)+IF(ISBLANK(K5),0,K5) -> 0.0335 | M5: 0.005 | N5: Set equal to expected RBA cash rate (≈ neutral) over 10Y. Bank-bill spread ~5–10 bps over OCR; immaterial for a 10Y forecast.
A6: Australian short duration bond | B6: Bloomberg AusBond Credit 0–3 Year Index | C6: ='Macro Assumptions'!$B$16 -> 0.0335 | E6: 0.003 | F6: 0.0055 | G6: -0.0005 | L6: =IF(ISBLANK(C6),0,C6)+IF(ISBLANK(D6),0,D6)+IF(ISBLANK(E6),0,E6)+IF(ISBLANK(F6),0,F6)+IF(ISBLANK(G6),0,G6)+IF(ISBLANK(H6),0,H6)+IF(ISBLANK(I6),0,I6)+IF(ISBLANK(J6),0,J6)+IF(ISBLANK(K6),0,K6) -> 0.0415 | M6: 0.015 | N6: Cash + short term premium (~30 bps for 0–3y bullet) + investment-grade credit spread (~55 bps blended) − low default losses (high IG quality, short tenor).
A7: Australian fixed income | B7: Bloomberg AusBond Composite 0+ Index | C7: ='Macro Assumptions'!$B$16 -> 0.0335 | E7: 0.0075 | F7: 0.003 | G7: -0.0005 | L7: =IF(ISBLANK(C7),0,C7)+IF(ISBLANK(D7),0,D7)+IF(ISBLANK(E7),0,E7)+IF(ISBLANK(F7),0,F7)+IF(ISBLANK(G7),0,G7)+IF(ISBLANK(H7),0,H7)+IF(ISBLANK(I7),0,I7)+IF(ISBLANK(J7),0,J7)+IF(ISBLANK(K7),0,K7) -> 0.0435 | M7: 0.05 | N7: Cash + term premium (~75 bps for ~6y duration) + semi-government / IG corp spread (~30 bps blended). Aligns with current 5–10Y AGB yields ~4.0–4.4%.
A8: Global fixed income (Hedged) | B8: Bloomberg Global Aggregate (hedged AUD) | C8: ='Macro Assumptions'!$B$17 -> 0.032 | E8: 0.008 | F8: 0.002 | G8: -0.0005 | K8: ='Macro Assumptions'!$B$25 -> 0 | L8: =IF(ISBLANK(C8),0,C8)+IF(ISBLANK(D8),0,D8)+IF(ISBLANK(E8),0,E8)+IF(ISBLANK(F8),0,F8)+IF(ISBLANK(G8),0,G8)+IF(ISBLANK(H8),0,H8)+IF(ISBLANK(I8),0,I8)+IF(ISBLANK(J8),0,J8)+IF(ISBLANK(K8),0,K8) -> 0.0415 | M8: 0.05 | N8: USD cash + term premium (~80 bps for ~7y duration of Global Agg) + securitised/IG sleeve (~20 bps) + AUD-USD hedge return (positive AU-US carry). Currency fully hedged.
A9: Global Credit (Hedged) | B9: Bloomberg Global Credit Index (hedged AUD) | C9: ='Macro Assumptions'!$B$17 -> 0.032 | E9: 0.008 | F9: 0.012 | G9: -0.002 | K9: ='Macro Assumptions'!$B$25 -> 0 | L9: =IF(ISBLANK(C9),0,C9)+IF(ISBLANK(D9),0,D9)+IF(ISBLANK(E9),0,E9)+IF(ISBLANK(F9),0,F9)+IF(ISBLANK(G9),0,G9)+IF(ISBLANK(H9),0,H9)+IF(ISBLANK(I9),0,I9)+IF(ISBLANK(J9),0,J9)+IF(ISBLANK(K9),0,K9) -> 0.05 | M9: 0.07 | N9: USD cash + term premium + IG corporate spread ~120 bps (currently inside long-run avg, modest reversion priced) − default losses ~20 bps + AUD hedge return.
A10: Australian listed equity | B10: S&P/ASX 300 Total Return Index | C10: 0.038 | D10: ='Macro Assumptions'!$B$12 -> 0.021 | H10: -0.005 | L10: =IF(ISBLANK(C10),0,C10)+IF(ISBLANK(D10),0,D10)+IF(ISBLANK(E10),0,E10)+IF(ISBLANK(F10),0,F10)+IF(ISBLANK(G10),0,G10)+IF(ISBLANK(H10),0,H10)+IF(ISBLANK(I10),0,I10)+IF(ISBLANK(J10),0,J10)+IF(ISBLANK(K10),0,K10) -> 0.054 | M10: 0.145 | N10: ASX dividend yield ~3.8% (excl. franking) + EPS growth anchored to AU nominal GDP (4.5%) − modest valuation headwind (PE re-rating from ~17x to LT avg ~15.5x). Franking credits add ~+0.7% if grossed up — excluded here for conservatism.
A11: Global listed equity (Unhedged) | B11: MSCI ACWI ex-Australia (unhedged AUD) | C11: 0.017 | D11: 0.05 | H11: -0.005 | J11: ='Macro Assumptions'!$B$24 -> 0.0015 | L11: =IF(ISBLANK(C11),0,C11)+IF(ISBLANK(D11),0,D11)+IF(ISBLANK(E11),0,E11)+IF(ISBLANK(F11),0,F11)+IF(ISBLANK(G11),0,G11)+IF(ISBLANK(H11),0,H11)+IF(ISBLANK(I11),0,I11)+IF(ISBLANK(J11),0,J11)+IF(ISBLANK(K11),0,K11) -> 0.0635 | M11: 0.135 | N11: Div yield ~1.7% + EPS growth ~5.0% (US 5.5% + Europe 4% + EM 6% blended) − valuation drag (US Shiller PE elevated, partly offset by cheaper non-US) + AUD appreciation drag on global FX basket.
A12: Global listed equity (Hedged) | B12: MSCI ACWI ex-Australia (100% hedged AUD) | C12: 0.017 | D12: 0.05 | H12: -0.005 | K12: ='Macro Assumptions'!$B$25 -> 0 | L12: =IF(ISBLANK(C12),0,C12)+IF(ISBLANK(D12),0,D12)+IF(ISBLANK(E12),0,E12)+IF(ISBLANK(F12),0,F12)+IF(ISBLANK(G12),0,G12)+IF(ISBLANK(H12),0,H12)+IF(ISBLANK(I12),0,I12)+IF(ISBLANK(J12),0,J12)+IF(ISBLANK(K12),0,K12) -> 0.062 | M12: 0.145 | N12: Same local-currency equity build as unhedged, but currency hedged — replaces FX drag with positive hedge return (AU cash − global cash differential). Slightly higher vol than unhedged as USD diversification benefit removed.
A13: Australian listed property | B13: S&P/ASX 300 A-REIT Index | C13: 0.05 | D13: 0.025 | H13: -0.007 | L13: =IF(ISBLANK(C13),0,C13)+IF(ISBLANK(D13),0,D13)+IF(ISBLANK(E13),0,E13)+IF(ISBLANK(F13),0,F13)+IF(ISBLANK(G13),0,G13)+IF(ISBLANK(H13),0,H13)+IF(ISBLANK(I13),0,I13)+IF(ISBLANK(J13),0,J13)+IF(ISBLANK(K13),0,K13) -> 0.068 | M13: 0.17 | N13: Distribution yield ~5.0% + DPS growth aligned to AU CPI (~2.5% rental escalators) − cap rate normalisation drag as bond yields stay structurally higher than 2010s average.
A14: Global Infrastructure unlisted (Unhedged) | B14: FTSE Global Core Infrastructure Index | C14: 0.035 | D14: 0.045 | H14: -0.003 | J14: -0.008 | L14: =IF(ISBLANK(C14),0,C14)+IF(ISBLANK(D14),0,D14)+IF(ISBLANK(E14),0,E14)+IF(ISBLANK(F14),0,F14)+IF(ISBLANK(G14),0,G14)+IF(ISBLANK(H14),0,H14)+IF(ISBLANK(I14),0,I14)+IF(ISBLANK(J14),0,J14)+IF(ISBLANK(K14),0,K14) -> 0.069 | M14: 0.13 | N14: Income yield ~3.5% (regulated utilities, transport) + cash flow growth ~4.5% (CPI-linked escalators + volume) − small valuation headwind + FX drag (~70% USD basket). FTSE Core Infra is listed proxy — true unlisted infra would be ~+50 bps return, lower vol.
A15: Global Private Equity | B15: LPX50 Listed Private Equity Index | C15: 0.015 | D15: 0.065 | H15: -0.005 | I15: 0.015 | J15: -0.008 | L15: =IF(ISBLANK(C15),0,C15)+IF(ISBLANK(D15),0,D15)+IF(ISBLANK(E15),0,E15)+IF(ISBLANK(F15),0,F15)+IF(ISBLANK(G15),0,G15)+IF(ISBLANK(H15),0,H15)+IF(ISBLANK(I15),0,I15)+IF(ISBLANK(J15),0,J15)+IF(ISBLANK(K15),0,K15) -> 0.082 | M15: 0.25 | N15: Listed-PE wrapper of global buyout exposure: yield ~1.5%, NAV growth ~6.5% (operating + leverage), small valuation drag, illiquidity/leverage premium ~+1.5% over public equity, FX drag (mostly USD/EUR). High vol due to listed wrapper + leverage.
A17: Notes:
A18: • Building-block convention: total return = starting income yield + cash-flow growth + (term/credit/illiquidity premia) + valuation drift + FX/hedge contribution.
A19: • Empty cells indicate the component is not relevant for that asset class (e.g. growth for fixed income, term premium for equity).
A20: • Returns are gross of fees. Apply IM Table 3A asset class costs and IM Table 4A trust-level fees when computing unit-trust net returns.
A21: • Forecast risk is annualised standard deviation of total return in AUD, calibrated to long-run history adjusted for forward-looking regime (higher rates, higher dispersion).
A22: • Cells in BLUE = hardcoded assumptions; GREEN = links to Macro Assumptions sheet; BLACK = derived formulas.
A25: Unit Trust Roll-Up (gross of trust fees)
A26: Component / Asset Class | B26: STI weight | C26: MTG weight | D26: LTG weight | E26: Asset Return | F26: STI contrib | G26: MTG contrib | H26: LTG contrib
A27: Cash | B27: 0.5 | C27: 0.075 | D27: 0.05 | E27: =L5 -> 0.0335 | F27: =B27*E27 -> 0.01675 | G27: =C27*E27 -> 0.0025125 | H27: =D27*E27 -> 0.001675
A28: Australian short duration bond | B28: 0.5 | C28: 0 | D28: 0 | E28: =L6 -> 0.0415 | F28: =B28*E28 -> 0.02075 | G28: =C28*E28 -> 0 | H28: =D28*E28 -> 0
A29: Australian fixed income | B29: 0 | C29: 0.15 | D29: 0 | E29: =L7 -> 0.0435 | F29: =B29*E29 -> 0 | G29: =C29*E29 -> 0.006525 | H29: =D29*E29 -> 0
A30: Global fixed income (Hedged) | B30: 0 | C30: 0.15 | D30: 0.05 | E30: =L8 -> 0.0415 | F30: =B30*E30 -> 0 | G30: =C30*E30 -> 0.006225 | H30: =D30*E30 -> 0.002075
A31: Global Credit (Hedged) | B31: 0 | C31: 0.125 | D31: 0.05 | E31: =L9 -> 0.05 | F31: =B31*E31 -> 0 | G31: =C31*E31 -> 0.00625 | H31: =D31*E31 -> 0.0025
A32: Australian listed equity | B32: 0 | C32: 0.15 | D32: 0.3 | E32: =L10 -> 0.054 | F32: =B32*E32 -> 0 | G32: =C32*E32 -> 0.0081 | H32: =D32*E32 -> 0.0162
A33: Global listed equity (Unhedged) | B33: 0 | C33: 0.15 | D33: 0.15 | E33: =L11 -> 0.0635 | F33: =B33*E33 -> 0 | G33: =C33*E33 -> 0.009525 | H33: =D33*E33 -> 0.009525
A34: Global listed equity (Hedged) | B34: 0 | C34: 0.15 | D34: 0.15 | E34: =L12 -> 0.062 | F34: =B34*E34 -> 0 | G34: =C34*E34 -> 0.0093 | H34: =D34*E34 -> 0.0093
A35: Australian listed property | B35: 0 | C35: 0.05 | D35: 0 | E35: =L13 -> 0.068 | F35: =B35*E35 -> 0 | G35: =C35*E35 -> 0.0034 | H35: =D35*E35 -> 0
A36: Global Infrastructure unlisted (Unhedged) | B36: 0 | C36: 0 | D36: 0.1 | E36: =L14 -> 0.069 | F36: =B36*E36 -> 0 | G36: =C36*E36 -> 0 | H36: =D36*E36 -> 0.0069
A37: Global Private Equity | B37: 0 | C37: 0 | D37: 0.15 | E37: =L15 -> 0.082 | F37: =B37*E37 -> 0 | G37: =C37*E37 -> 0 | H37: =D37*E37 -> 0.0123
A38: Weighted gross return | B38: =SUM(B27:B37) -> 1 | C38: =SUM(C27:C37) -> 1 | D38: =SUM(D27:D37) -> 1 | F38: =SUM(F27:F37) -> 0.0375 | G38: =SUM(G27:G37) -> 0.0518375 | H38: =SUM(H27:H37) -> 0.060475
A39: Less: trust ongoing cost (IM Table 4A) | F39: -0.00126 | G39: -0.00358 | H39: -0.00488
A40: Less: weighted asset class cost (IM Table 3A) | F40: -0.00055 | G40: -0.00163 | H40: -0.00255
A41: Net expected return (10Y, p.a.) | F41: =F38+F39+F40 -> 0.03569 | G41: =G38+G39+G40 -> 0.0466275 | H41: =H38+H39+H40 -> 0.053045
A43: Forecast risk (vol p.a.) — placeholder; replace with Refinitiv historical vol
A44: STI / MTG / LTG forecast volatility (placeholder) | F44: 0.01 | G44: 0.075 | H44: 0.105
A46: Trust-level vols above are placeholders consistent with diversified multi-asset behaviour assuming typical 0.4–0.6 cross-asset correlation. Replace with Refinitiv-derived historical vol of each unit trust's index-weighted return series before final submission.

Sheet Methodology & Sources
A1: NSWDF 10Y Capital Market Assumptions — Methodology & Sources
A3: 1. Methodology overview
A4: Topic | B4: Description | C4: Notes
A5: Approach | B5: Building-block (CMA) framework, aligned with institutional practice (J.P. Morgan LTCMA, BlackRock CMA, Vanguard VCMM).
A6: Horizon | B6: 10 years from 2 April 2026 — matches NSWDF rolling 10-year measurement horizon and Board CPI+2.5% return target.
A7: Currency | B7: All returns expressed in AUD. Hedged exposures convert local currency returns at hedge return = AU cash − foreign cash differential.
A8: Gross / Net basis | B8: Asset-class returns are GROSS of fees. Trust-level rollups apply IM Table 3A asset-class costs and IM Table 4A ongoing trust costs.
A9: Why building-block, not pure historical? | B9: 10Y forward returns differ materially from history because (a) starting yields are higher than 2010s averages, (b) equity valuations are above LT, (c) AUD is below PPP. A building-block approach disentangles starting conditions from steady-state assumptions.
A10: Geometric vs arithmetic | B10: Forecast returns are presented as geometric (compound) annualised returns over 10 years. Vol is annualised standard deviation of 1-year returns.
A12: 2. Building-block formula
A13: Asset class | B13: Formula | C13: Key parameters
A14: Cash | B14: Avg expected RBA cash rate over 10Y (≈ neutral nominal rate)
A15: Aus short-duration bond | B15: Cash + term premium + IG credit spread − default losses | C15: Term premium ~30 bps (0–3y); IG spread ~55 bps; defaults ~5 bps
A16: Aus fixed income | B16: Cash + term premium (~6y dur) + semi-gov / IG sleeve − default losses | C16: Term ~75 bps; spread ~30 bps
A17: Global FI hedged | B17: US cash + term premium + IG sleeve − default + AUD-USD hedge return | C17: Hedge return = AU cash − US cash
A18: Global Credit hedged | B18: US cash + term premium + IG corp spread − default losses + hedge return | C18: IG spread ~120 bps; defaults ~20 bps
A19: Australian listed equity | B19: Dividend yield + nominal EPS growth + valuation drift | C19: EPS growth ≈ AU nominal GDP; valuation = LT PE / current PE
A20: Global eq unhedged | B20: Div yield + nominal EPS growth + valuation drift + FX contribution | C20: FX = AUD appreciation against weighted ACWI ex-Aus basket (negative for unhedged AUD investor)
A21: Global eq hedged | B21: Div yield + nominal EPS growth + valuation drift + hedge return | C21: Replaces FX with hedge return
A22: Aus listed property | B22: Distribution yield + DPS growth + cap-rate drift | C22: DPS growth ≈ AU CPI (rental escalators)
A23: Global infra unhedged | B23: Income yield + cash flow growth + valuation drift + FX | C23: Growth ≈ CPI + volume; FX drag ~80 bps
A24: Global Private Equity | B24: Listed equity build + illiquidity/leverage premium + FX | C24: Illiquidity premium ~150 bps (conservative)
A26: 3. Data sources
A27: Topic | B27: Source | C27: URL / reference
A28: Macro / inflation | B28: RBA Statement on Monetary Policy (Feb / May 2026 editions) | C28: https://www.rba.gov.au/publications/smp/
A29: Macro / inflation | B29: Australian Bureau of Statistics CPI series 6401.0 | C29: https://www.abs.gov.au/statistics/economy/price-indexes-and-inflation
A30: Macro / inflation | B30: Federal Reserve Summary of Economic Projections (latest FOMC) | C30: https://www.federalreserve.gov/monetarypolicy/fomccalendars.htm
A31: Macro / inflation | B31: BLS CPI series | C31: https://www.bls.gov/cpi/
A32: Real growth | B32: Australian Treasury Intergenerational Report 2023 | C32: https://treasury.gov.au/publication/2023-intergenerational-report
A33: Real growth | B33: CBO Long-Term Budget Outlook (latest) | C33: https://www.cbo.gov/topics/budget
A34: Real growth | B34: IMF World Economic Outlook (Apr 2026) | C34: https://www.imf.org/en/Publications/WEO
A35: Neutral rates | B35: RBA Bulletin: 'Estimating the Neutral Rate' (most recent) | C35: https://www.rba.gov.au/publications/bulletin/
A36: Neutral rates | B36: FRBNY r-star estimates (Holston-Laubach-Williams) | C36: https://www.newyorkfed.org/research/policy/rstar
A37: FX / PPP | B37: OECD Purchasing Power Parities | C37: https://data.oecd.org/conversion/purchasing-power-parities-ppp.htm
A38: FX / PPP | B38: IMF Real Effective Exchange Rate database | C38: https://data.imf.org/
... A49: Benchmark CMAs (cross-check) | B49: Vanguard Capital Markets Model (VCMM) | C49: https://corporate.vanguard.com/content/corporatesite/us/en/corp/research-and-commentary.html
A51: 4. Limitations and caveats
A52: Limitation | B52: Description
A53: Refinitiv data not loaded | B53: Project brief specifies 'all modelling must use Refinitiv data from the provided portfolios'. Forecast inputs here are anchored to publicly available benchmarks; cross-check against Refinitiv historical series before final submission and replace placeholder vol numbers.
A54: Listed proxies for unlisted | B54: Global Infrastructure (FTSE Core Infra) and Global PE (LPX50) use listed proxies per IM Table 3A. True unlisted infra/PE returns are typically 50–150 bps higher with materially lower vol (smoothed valuations); IM mandates these proxies, so we do not adjust.
...
